Workbook

Sheet OutOfStock
B1: วัตถุดิบต้องซื้อ | C1: Price
B2: {=_xlfn._xlws.FILTER(Ingredient!E2:E85,Ingredient!I2:I85=0)} -> น้ำปลา | C2: =VLOOKUP(B2,Ingredient!E:K,7,FALSE) -> 30
B3: ซีอิ๊วขาว | C3: =VLOOKUP(B3,Ingredient!E:K,7,FALSE) -> 40
B4: ซีอิ๊วดำ / ซีอิ๊วหวาน | C4: =VLOOKUP(B4,Ingredient!E:K,7,FALSE) -> 30
B5: ซอสหอยนางรม | C5: =VLOOKUP(B5,Ingredient!E:K,7,FALSE) -> 40
B6: น้ำส้มสายชู | C6: =VLOOKUP(B6,Ingredient!E:K,7,FALSE) -> 10
B7: ซอสปรุงรสฝาเขียว | C7: =VLOOKUP(B7,Ingredient!E:K,7,FALSE) -> 20
B8: ซอสญี่ปุ่น | C8: =VLOOKUP(B8,Ingredient!E:K,7,FALSE) -> 0
B9: น้ำตาลทราย | C9: =VLOOKUP(B9,Ingredient!E:K,7,FALSE) -> 0
B10: น้ำตาลปี๊บ / น้ำตาลมะพร้าว | C10: =VLOOKUP(B10,Ingredient!E:K,7,FALSE) -> 0
B11: น้ำตาลกรวด | C11: =VLOOKUP(B11,Ingredient!E:K,7,FALSE) -> 0
B12: น้ำตาลทรายแดง | C12: =VLOOKUP(B12,Ingredient!E:K,7,FALSE) -> 0
B13: ผงชูรส | C13: =VLOOKUP(B13,Ingredient!E:K,7,FALSE) -> 0
B14: ผงพะโล้ | C14: =VLOOKUP(B14,Ingredient!E:K,7,FALSE) -> 0
... B41: น้ำพริกเผา | C41: =VLOOKUP(B41,Ingredient!E:K,7,FALSE) -> 0

Sheet Ingredient
E1: วัตถุดิบ | F1: Ingredient | H1: In Use | I1: Stock | J1: Unit | K1: Price
A2: =INDEX(Classify!C:C,MATCH(Ingredient!B2,Classify!A:A,0)) -> LSS | B2: 001 | C2: 1 | D2: =_xlfn.TEXTJOIN("_",FALSE,A2,B2,C2,) -> LSS_001_1_ | E2: น้ำปลา | F2: Fish Sauce | H2: 1 | I2: 0 | K2: 30
A3: =INDEX(Classify!C:C,MATCH(Ingredient!B3,Classify!A:A,0)) -> LSS | B3: 001 | C3: 2 | D3: =_xlfn.TEXTJOIN("_",FALSE,A3,B3,C3,) -> LSS_001_2_ | E3: ซีอิ๊วขาว | F3: Light Soy Sauce | H3: 0 | I3: 0 | K3: 40
A4: =INDEX(Classify!C:C,MATCH(Ingredient!B4,Classify!A:A,0)) -> LSS | B4: 001 | C4: 3 | D4: =_xlfn.TEXTJOIN("_",FALSE,A4,B4,C4,) -> LSS_001_3_ | E4: ซีอิ๊วดำ / ซีอิ๊วหวาน | F4: Dark / Sweet Soy Sauce | H4: 0 | I4: 0 | K4: 30
A5: =INDEX(Classify!C:C,MATCH(Ingredient!B5,Classify!A:A,0)) -> LSS | B5: 001 | C5: 4 | D5: =_xlfn.TEXTJOIN("_",FALSE,A5,B5,C5,) -> LSS_001_4_ | E5: ซอสหอยนางรม | F5: Oyster Sauce | H5: 1 | I5: 0 | K5: 40
A6: =INDEX(Classify!C:C,MATCH(Ingredient!B6,Classify!A:A,0)) -> LSS | B6: 001 | C6: 5 | D6: =_xlfn.TEXTJOIN("_",FALSE,A6,B6,C6,) -> LSS_001_5_ | E6: น้ำส้มสายชู | F6: Vinegar | H6: 1 | I6: 0 | K6: 10
A7: =INDEX(Classify!C:C,MATCH(Ingredient!B7,Classify!A:A,0)) -> LSS | B7: 001 | C7: 6 | D7: =_xlfn.TEXTJOIN("_",FALSE,A7,B7,C7,) -> LSS_001_6_ | E7: ซอสปรุงรสฝาเขียว | F7: Seasoning Sauce | H7: 1 | I7: 0 | K7: 20
A8: =INDEX(Classify!C:C,MATCH(Ingredient!B8,Classify!A:A,0)) -> LSS | B8: 001 | C8: 7 | D8: =_xlfn.TEXTJOIN("_",FALSE,A8,B8,C8,) -> LSS_001_7_ | E8: ซอสญี่ปุ่น | F8: Japanese Soy Sauce | H8: 1 | I8: 0
A9: =INDEX(Classify!C:C,MATCH(Ingredient!B9,Classify!A:A,0)) -> #N/A | C9: 8 | D9: =_xlfn.TEXTJOIN("_",FALSE,A9,B9,C9,) -> #N/A | I9: 1
A10: =INDEX(Classify!C:C,MATCH(Ingredient!B10,Classify!A:A,0)) -> DSS | B10: 002 | C10: 9 | D10: =_xlfn.TEXTJOIN("_",FALSE,A10,B10,C10,) -> DSS_002_9_ | E10: น้ำตาลทราย | F10: Sugar | H10: 1 | I10: 0
A11: =INDEX(Classify!C:C,MATCH(Ingredient!B11,Classify!A:A,0)) -> DSS | B11: 002 | C11: 10 | D11: =_xlfn.TEXTJOIN("_",FALSE,A11,B11,C11,) -> DSS_002_10_ | E11: น้ำตาลปี๊บ / น้ำตาลมะพร้าว | F11: Palm Sugar | H11: 1 | I11: 0
A12: =INDEX(Classify!C:C,MATCH(Ingredient!B12,Classify!A:A,0)) -> DSS | B12: 002 | C12: 11 | D12: =_xlfn.TEXTJOIN("_",FALSE,A12,B12,C12,) -> DSS_002_11_ | E12: น้ำตาลกรวด | F12: Rock Sugar | H12: 1 | I12: 0
A13: =INDEX(Classify!C:C,MATCH(Ingredient!B13,Classify!A:A,0)) -> DSS | B13: 002 | C13: 12 | D13: =_xlfn.TEXTJOIN("_",FALSE,A13,B13,C13,) -> DSS_002_12_ | E13: น้ำตาลทรายแดง | F13: Brown Sugar | H13: 0 | I13: 0
A14: =INDEX(Classify!C:C,MATCH(Ingredient!B14,Classify!A:A,0)) -> DSS | B14: 002 | C14: 13 | D14: =_xlfn.TEXTJOIN("_",FALSE,A14,B14,C14,) -> DSS_002_13_ | E14: เกลือ | F14: Salt | H14: 1 | I14: 5
A15: =INDEX(Classify!C:C,MATCH(Ingredient!B15,Classify!A:A,0)) -> DSS | B15: 002 | C15: 14 | D15: =_xlfn.TEXTJOIN("_",FALSE,A15,B15,C15,) -> DSS_002_14_ | E15: ผงชูรส | F15: MSG | H15: 0 | I15: 0
A16: =INDEX(Classify!C:C,MATCH(Ingredient!B16,Classify!A:A,0)) -> DSS | B16: 002 | C16: 15 | D16: =_xlfn.TEXTJOIN("_",FALSE,A16,B16,C16,) -> DSS_002_15_ | E16: ผงปรุงรสหมู/ไก่ | F16: Bouillon Powder | H16: 1 | I16: 1
A17: =INDEX(Classify!C:C,MATCH(Ingredient!B17,Classify!A:A,0)) -> DSS | B17: 002 | C17: 16 | D17: =_xlfn.TEXTJOIN("_",FALSE,A17,B17,C17,) -> DSS_002_16_ | E17: ผงพะโล้ | F17: Five-Spice Powder | H17: 0 | I17: 0
A18: =INDEX(Classify!C:C,MATCH(Ingredient!B18,Classify!A:A,0)) -> #N/A | C18: 17 | D18: =_xlfn.TEXTJOIN("_",FALSE,A18,B18,C18,) -> #N/A | I18: 1
A19: =INDEX(Classify!C:C,MATCH(Ingredient!B19,Classify!A:A,0)) -> FHB | B19: 003 | C19: 18 | D19: =_xlfn.TEXTJOIN("_",FALSE,A19,B19,C19,) -> FHB_003_18_ | E19: กระเทียม | F19: Garlic | H19: 1 | I19: 8
A20: =INDEX(Classify!C:C,MATCH(Ingredient!B20,Classify!A:A,0)) -> FHB | B20: 003 | C20: 19 | D20: =_xlfn.TEXTJOIN("_",FALSE,A20,B20,C20,) -> FHB_003_19_ | E20: หอมแดง | F20: Shallot | H20: 1 | I20: 4
A21: =INDEX(Classify!C:C,MATCH(Ingredient!B21,Classify!A:A,0)) -> FHB | B21: 003 | C21: 20 | D21: =_xlfn.TEXTJOIN("_",FALSE,A21,B21,C21,) -> FHB_003_20_ | E21: พริกขี้หนู / พริกจินดา | F21: Chili | H21: 1 | I21: 0
A22: =INDEX(Classify!C:C,MATCH(Ingredient!B22,Classify!A:A,0)) -> FHB | B22: 003 | C22: 21 | D22: =_xlfn.TEXTJOIN("_",FALSE,A22,B22,C22,) -> FHB_003_21_ | E22: ข่า | F22: Galangal | I22: 1
A23: =INDEX(Classify!C:C,MATCH(Ingredient!B23,Classify!A:A,0)) -> FHB | B23: 003 | C23: 22 | D23: =_xlfn.TEXTJOIN("_",FALSE,A23,B23,C23,) -> FHB_003_22_ | E23: ตะไคร้ | F23: Lemongrass | I23: 1
A24: =INDEX(Classify!C:C,MATCH(Ingredient!B24,Classify!A:A,0)) -> FHB | B24: 003 | C24: 23 | D24: =_xlfn.TEXTJOIN("_",FALSE,A24,B24,C24,) -> FHB_003_23_ | E24: ใบมะกรูด | F24: Kaffir Lime Leaves | I24: 1
A25: =INDEX(Classify!C:C,MATCH(Ingredient!B25,Classify!A:A,0)) -> FHB | B25: 003 | C25: 24 | D25: =_xlfn.TEXTJOIN("_",FALSE,A25,B25,C25,) -> FHB_003_24_ | E25: รากผักชี / ผักชี | F25: Coriander Root / Cilantro | I25: 1
A26: =INDEX(Classify!C:C,MATCH(Ingredient!B26,Classify!A:A,0)) -> FHB | B26: 003 | C26: 25 | D26: =_xlfn.TEXTJOIN("_",FALSE,A26,B26,C26,) -> FHB_003_25_ | E26: กะเพรา | F26: Holy Basil | I26: 1
A27: =INDEX(Classify!C:C,MATCH(Ingredient!B27,Classify!A:A,0)) -> FHB | B27: 003 | C27: 26 | D27: =_xlfn.TEXTJOIN("_",FALSE,A27,B27,C27,) -> FHB_003_26_ | E27: โหระพา | F27: Thai Basil | I27: 0
A28: =INDEX(Classify!C:C,MATCH(Ingredient!B28,Classify!A:A,0)) -> FHB | B28: 003 | C28: 27 | D28: =_xlfn.TEXTJOIN("_",FALSE,A28,B28,C28,) -> FHB_003_27_ | E28: มะนาว | F28: Lime | I28: 1
A29: =INDEX(Classify!C:C,MATCH(Ingredient!B29,Classify!A:A,0)) -> #N/A | C29: 28 | D29: =_xlfn.TEXTJOIN("_",FALSE,A29,B29,C29,) -> #N/A | I29: 1
A30: =INDEX(Classify!C:C,MATCH(Ingredient!B30,Classify!A:A,0)) -> DHB | B30: 004 | C30: 29 | D30: =_xlfn.TEXTJOIN("_",FALSE,A30,B30,C30,) -> DHB_004_29_ | E30: พริกไทยเม็ดขาว/ดำ | F30: White/Black Peppercorns | H30: 1 | I30: 0
A31: =INDEX(Classify!C:C,MATCH(Ingredient!B31,Classify!A:A,0)) -> DHB | B31: 004 | C31: 30 | D31: =_xlfn.TEXTJOIN("_",FALSE,A31,B31,C31,) -> DHB_004_30_ | E31: พริกแห้ง | F31: Dried Chili | I31: 1
A32: =INDEX(Classify!C:C,MATCH(Ingredient!B32,Classify!A:A,0)) -> DHB | B32: 004 | C32: 31 | D32: =_xlfn.TEXTJOIN("_",FALSE,A32,B32,C32,) -> DHB_004_31_ | E32: พริกป่น | F32: Chili Powder | H32: 1 | I32: 0
A33: =INDEX(Classify!C:C,MATCH(Ingredient!B33,Classify!A:A,0)) -> DHB | B33: 004 | C33: 32 | D33: =_xlfn.TEXTJOIN("_",FALSE,A33,B33,C33,) -> DHB_004_32_ | E33: กะปิ | F33: Shrimp Paste | H33: 0 | I33: 0
A34: =INDEX(Classify!C:C,MATCH(Ingredient!B34,Classify!A:A,0)) -> DHB | B34: 004 | C34: 33 | D34: =_xlfn.TEXTJOIN("_",FALSE,A34,B34,C34,) -> DHB_004_33_ | E34: มะขามเปียก | F34: Tamarind Paste | I34: 1
A35: =INDEX(Classify!C:C,MATCH(Ingredient!B35,Classify!A:A,0)) -> #N/A | C35: 34 | D35: =_xlfn.TEXTJOIN("_",FALSE,A35,B35,C35,) -> #N/A | I35: 1
A36: =INDEX(Classify!C:C,MATCH(Ingredient!B36,Classify!A:A,0)) -> OLF | B36: 005 | C36: 35 | D36: =_xlfn.TEXTJOIN("_",FALSE,A36,B36,C36,) -> OLF_005_35_ | E36: น้ำมันพืช | F36: Vegetable Oil - สำหรับผัด/ทอดทั่วไป | H36: 1 | I36: 0
A37: =INDEX(Classify!C:C,MATCH(Ingredient!B37,Classify!A:A,0)) -> OLF | B37: 005 | C37: 36 | D37: =_xlfn.TEXTJOIN("_",FALSE,A37,B37,C37,) -> OLF_005_36_ | E37: น้ำมันหมู | F37: Lard | H37: 1 | I37: 0
A38: =INDEX(Classify!C:C,MATCH(Ingredient!B38,Classify!A:A,0)) -> OLF | B38: 005 | C38: 37 | D38: =_xlfn.TEXTJOIN("_",FALSE,A38,B38,C38,) -> OLF_005_37_ | E38: กะทิ | F38: Coconut Milk - ทั้งแบบกล่องและคั้นสด | H38: 0 | I38: 0
A39: =INDEX(Classify!C:C,MATCH(Ingredient!B39,Classify!A:A,0)) -> #N/A | C39: 38 | D39: =_xlfn.TEXTJOIN("_",FALSE,A39,B39,C39,) -> #N/A | I39: 1
A40: =INDEX(Classify!C:C,MATCH(Ingredient!B40,Classify!A:A,0)) -> FLO | B40: 006 | C40: 39 | D40: =_xlfn.TEXTJOIN("_",FALSE,A40,B40,C40,) -> FLO_006_39_ | E40: แป้งมันสำปะหลัง | F40: Tapioca Starch | H40: 1 | I40: 0
...

Sheet Unit

Sheet Classify
A1: 001 | B1: เครื่องปรุงรสของเหลว (Liquid Seasonings) | C1: LSS
A2: 002 | B2: เครื่องปรุงรสของแห้งและผง (Dry Seasonings & Powders) | C2: DSS
A3: 003 | B3: สมุนไพรและเครื่องเทศสด (Fresh Herbs & Spices) | C3: FHB
A4: 004 | B4: เครื่องเทศแห้ง (Dry Spices) | C4: DHB
A5: 005 | B5: น้ำมันและไขมัน (Oils & Fats) | C5: OLF
A6: 006 | B6: แป้งและส่วนผสมแห้ง (Flour & Dry Ingredients) | C6: FLO
A7: 007 | B7: เนื้อสัตว์และโปรตีนหลัก (Meat & Proteins) | C7: MET
A8: 008 | B8: ผักสดพื้นฐาน (Everyday Vegetables) | C8: VET
A9: 009 | B9: ข้าวและเส้น (Rice & Noodles) | C9: RCE
A10: 010 | B10: เครื่องแกงสำเร็จรูป (Ready-made Curry Pastes) | C10: CUR
